| test.cpp:6:5:6:26 | throw ... | The $@ thrown here is a possible duplicate of the $@ thrown $@. | test.cpp:6:5:6:26 | call to exception | std::exception exception | test.cpp:14:5:14:26 | call to exception | exception | test.cpp:14:5:14:26 | throw ... | here |
| test.cpp:8:5:8:53 | throw ... | The $@ thrown here is a possible duplicate of the $@ thrown $@. | test.cpp:8:5:8:53 | call to runtime_error | std::runtime_error exception | test.cpp:16:5:16:53 | call to runtime_error | exception | test.cpp:16:5:16:53 | throw ... | here |
| test.cpp:14:5:14:26 | throw ... | The $@ thrown here is a possible duplicate of the $@ thrown $@. | test.cpp:14:5:14:26 | call to exception | std::exception exception | test.cpp:6:5:6:26 | call to exception | exception | test.cpp:6:5:6:26 | throw ... | here |
| test.cpp:16:5:16:53 | throw ... | The $@ thrown here is a possible duplicate of the $@ thrown $@. | test.cpp:16:5:16:53 | call to runtime_error | std::runtime_error exception | test.cpp:8:5:8:53 | call to runtime_error | exception | test.cpp:8:5:8:53 | throw ... | here |
| test.cpp:26:5:26:50 | throw ... | The $@ thrown here is a possible duplicate of the $@ thrown $@. | test.cpp:26:5:26:50 | call to runtime_error | std::runtime_error exception | test.cpp:28:5:28:50 | call to runtime_error | exception | test.cpp:28:5:28:50 | throw ... | here |
| test.cpp:28:5:28:50 | throw ... | The $@ thrown here is a possible duplicate of the $@ thrown $@. | test.cpp:28:5:28:50 | call to runtime_error | std::runtime_error exception | test.cpp:26:5:26:50 | call to runtime_error | exception | test.cpp:26:5:26:50 | throw ... | here |
| test.cpp:36:5:36:58 | throw ... | The $@ thrown here is a possible duplicate of the $@ thrown $@. | test.cpp:36:5:36:58 | call to runtime_error | std::runtime_error exception | test.cpp:38:5:38:58 | call to runtime_error | exception | test.cpp:38:5:38:58 | throw ... | here |
| test.cpp:38:5:38:58 | throw ... | The $@ thrown here is a possible duplicate of the $@ thrown $@. | test.cpp:38:5:38:58 | call to runtime_error | std::runtime_error exception | test.cpp:36:5:36:58 | call to runtime_error | exception | test.cpp:36:5:36:58 | throw ... | here |
