| test_noexcept_false.cpp:7:5:7:8 | main | Main function has a $@ which is not within a try block with a catch-all ('catch(...)') handler. | test_noexcept_false.cpp:8:3:8:3 | call to f | function call that may throw |
